Workbook

Sheet About
A1: Kobold Clicker: every tooltip, rated
A2: Exported | B2: 2026-10-10, from the working tree (branch dialogue-voices)
A4: Sheets
A5: Tooltips | B5: Every tooltip a player can meet, one row each, with two ratings, a verdict and, where it helps, a rewrite. Filter by Area, Kind or Verdict.
A6: Developer only | B6: The tooltips of the developer screens, which a release build does not have. Listed, not rated.
A7: Patterns | B7: Habits that run through the tooltips as a whole.
A9: Counts
A10: Rows | B10: =COUNTA(Tooltips!F2:F217) -> 216
A11: Keep | B11: =COUNTIF(Tooltips!K2:K217,"Keep") -> 73
A12: Reword | B12: =COUNTIF(Tooltips!K2:K217,"Reword") -> 54
A13: Cut | B13: =COUNTIF(Tooltips!K2:K217,"Cut") -> 85
A14: Check | B14: =COUNTIF(Tooltips!K2:K217,"Check") -> 2
A15: Never shows | B15: =COUNTIF(Tooltips!K2:K217,"Never shows") -> 2
A16: Explains it poorly (1 or 2) | B16: =COUNTIF(Tooltips!I2:I217,"<=2") -> 14
A17: Not needed (1 or 2) | B17: =COUNTIF(Tooltips!J2:J217,"<=2") -> 41
A18: Needed and poorly explained (Needed 4-5, Explains 1-3) | B18: =COUNTIFS(Tooltips!J2:J217,">=4",Tooltips!I2:I217,"<=3") -> 41
A19: Average: Explains | B19: =ROUND(AVERAGE(Tooltips!I2:I217),1) -> 4.2
A20: Average: Needed | B20: =ROUND(AVERAGE(Tooltips!J2:J217),1) -> 3.8
A21: On a control that cannot show it (Kind = Never shown) | B21: =COUNTIF(Tooltips!E2:E217,"Never shown") -> 9
A23: Explains (1-5) | B23: How well the words explain the thing they are on.
A24: 5 | B24: Says exactly what the press or the thing does, in plain words.
A25: 4 | B25: Clear, with a small wobble: an odd word, a missing detail.
A26: 3 | B26: Understood on a second read, or leaves out something the player needs.
A27: 2 | B27: Likely to be misread, or leans on a word the game has not explained.
A28: 1 | B28: Does not explain, or says something untrue.
A30: Needed (1-5) | B30: How much the player would lose without it.
A31: 5 | B31: The only place a rule, a number or the reason for a grey button is said.
A32: 4 | B32: Names or explains a control with no words of its own (an icon), or adds a real fact.
A33: 3 | B33: Helpful, but the player would manage without it.
A34: 2 | B34: Mostly repeats the words on the button.
A35: 1 | B35: Repeats the button exactly, or cannot be seen in play.
A37: Verdict
A38: Keep | B38: Does its job.
A39: Reword | B39: Worth having, and the wording gets in its way. A rewrite is offered.
A40: Cut | B40: Repeats its button. Removing it loses nothing, or it could be spent on a fact instead.
A41: Check | B41: Out of date, untrue in some case, or not reachable in play. Needs your eye, not only new words.
A42: Never shows | B42: Worth reading, but written on a control the tip card cannot reach.
A44: How to read a row
A45: Kind | B45: Tooltip: the cream tip card that comes up after half a second on a control. Tooltip: why a button is grey: the same card, on a dead button. Hover card: the sentence on an orb's, rune's or super orb's card. Never shown: text set as a tooltip that no card can show.
A46: Text | B46: As it is in the source. %d, %s and %.1f stand for a number or a name filled in as the game runs, and %% is a percent sign.
...

Sheet Tooltips
A1: # | B1: Area | C1: Where it shows | D1: On | E1: Kind | F1: Text | G1: Example, as shown | H1: Length | I1: Explains (1-5) | J1: Needed (1-5) | K1: Verdict | L1: Why | M1: Suggested rewrite | N1: File | O1: Line
A2: 10 | B2: Map and main screen | C2: Corner panel | D2: Experience bar | E2: Tooltip | F2: %s / %s XP | G2: 120 / 450 XP | H2: =LEN(F2) -> 10 | I2: 5 | J2: 5 | K2: Keep | L2: The only place the experience held and needed are given as numbers. | N2: Scenes/UI/character_panel.gd | O2: 290
A3: 14 | B3: Map and main screen | C3: Tile panel | D3: Chart button | E3: Tooltip | F3: Fight for this tile and what lies behind it | H3: =LEN(F3) -> 43 | I3: 3 | J3: 5 | K3: Reword | L3: Chart is the game's own verb and this is the only place it is defined. 'What lies behind it' is the vague part: winning lifts the fog off the tile and the land in sight of it. | M3: Fight for this tile. Win, and it and the land around it come out of the fog | N3: Scenes/main_scene.gd | O3: 1904
A4: 15 | B4: Map and main screen | C4: Tile panel | D4: Farm button | E4: Tooltip | F4: Fight here for as long as you like, for the loot | H4: =LEN(F4) -> 48 | I4: 5 | J4: 5 | K4: Keep | L4: Says what farming is, that it has no end, and why you would. A model tooltip. | N4: Scenes/main_scene.gd | O4: 1905
A5: 16 | B5: Map and main screen | C5: Tile panel | D5: Chart and Farm, greyed | E5: Tooltip: why a button is grey | F5: Your bag is too heavy to fight with. Sell or discard gear until it holds %d or fewer | G5: Your bag is too heavy to fight with. Sell or discard gear until it holds 40 or fewer | H5: =LEN(F5) -> 84 | I5: 4 | J5: 5 | K5: Reword | L5: The only place the reason and the limit are said, and it says how to fix it. Two wobbles: nothing else in the game weighs anything (elsewhere the bag is 'full'), and 'or fewer' has no noun. | M5: Your bag is over its limit. Sell or discard gear until it holds %d items or fewer | N5: Scenes/main_scene.gd | O5: 1908
A6: 19 | B6: Map and main screen | C6: Tile panel, on the cave | D6: Enter cave button | E6: Tooltip | F6: Go down to depth %d. Kill Gollux to go deeper: each depth won is a skull for your curses | G6: Go down to depth 3. Kill Gollux to go deeper: each depth won is a skull for your curses | H6: =LEN(F6) -> 88 | I6: 3 | J6: 5 | K6: Reword | L6: Carries the whole rule of the cave, and nothing else on the panel does. The last part is hard: 'a skull for your curses' only means something to a player who has already seen the curse table. | M6: Go down to depth %d. Kill Gollux to win the depth. Each depth won gives one more skull to spend on curses | N6: Scenes/main_scene.gd | O6: 2369
A7: 20 | B7: Map and main screen | C7: Ice wall's tile panel: Unlocks | D7: An orb's row (walls 1 and 2) | E7: Tooltip | F7: (the orb's own description, as on its card) | H7: =LEN(F7) -> 43 | I7: 3 | J7: 5 | K7: Keep | L7: The right thing to show: the wall promises an orb and the row says what it does. As clear as the orb's sentence is, see the Orb card rows. | N7: Scenes/Items/wall_unlocks.gd | O7: 59
A8: 21 | B8: Map and main screen | C8: Ice wall's tile panel: Unlocks | D8: Gollux row (wall 3) | E8: Tooltip | F8: His cave appears in every world | H8: =LEN(F8) -> 31 | I8: 3 | J8: 5 | K8: Reword | L8: The first time the player reads the name. It says where he is and not what he is, or why his cave is worth finding. | M8: A boss in a cave of his own. The cave is in every world from now on | N8: Scenes/Items/wall_unlocks.gd | O8: 28
A9: 22 | B9: Map and main screen | C9: Ice wall's tile panel: Unlocks | D9: Runes row (wall 3) | E9: Tooltip | F9: Dropped in Gollux's cave, they give a charted tile modifiers | H9: =LEN(F9) -> 60 | I9: 3 | J9: 5 | K9: Reword | L9: Says where runes come from. 'Give a tile modifiers' does not say whether that is good for the player. | M9: Dropped in Gollux's cave. Spend one on a tile you have charted to add or change its modifiers | N9: Scenes/Items/wall_unlocks.gd | O9: 30
A10: 23 | B10: Map and main screen | C10: Ice wall's tile panel: Unlocks | D10: Distant charting row (wall 4) | E10: Tooltip | F10: Chart any tile you can see, fighting for every tile on the way | H10: =LEN(F10) -> 62 | I10: 5 | J10: 5 | K10: Keep | L10: The whole rule in one line, cost included. | N10: Scenes/Items/wall_unlocks.gd | O10: 32
A11: 24 | B11: Map and main screen | C11: Ice wall's tile panel: Unlocks | D11: Item filter row (wall 6) | E11: Tooltip | F11: Leave behind the loot you do not want | H11: =LEN(F11) -> 37 | I11: 4 | J11: 5 | K11: Reword | L11: Clear about what it does. It does not say where the filter is, and nothing points to Settings. | M11: Leave behind the loot you do not want. Set it in Settings | N11: Scenes/Items/wall_unlocks.gd | O11: 34
A12: 25 | B12: Map and main screen | C12: Ice wall's tile panel: Unlocks | D12: Abilities row (wall 7) | E12: Tooltip | F12: Skill nodes that put a button in the fight | H12: =LEN(F12) -> 42 | I12: 3 | J12: 5 | K12: Check | L12: 'Put a button in the fight' describes the interface, not what the player gains. Also check: the abilities are not built yet, so the row promises something the game does not have. | M12: Skill nodes that give you an ability to use during a fight | N12: Scenes/Items/wall_unlocks.gd | O12: 36
A13: 26 | B13: Map and main screen | C13: Ice wall's tile panel: Unlocks | D13: Skill branch row (walls 3, 5, 8 and on) | E13: Tooltip | F13: The skill tree's root takes %d more node%s | G13: The skill tree's root takes 1 more node | H13: =LEN(F13) -> 42 | I13: 3 | J13: 5 | K13: Reword | L13: The row's name ('+1 skill branch') and the tooltip use two words, branch and node, for the same gain. 'The root takes' reads oddly. | M13: %d more skill node%s can be joined to the root of your skill tree | N13: Scenes/Items/wall_unlocks.gd | O13: 66
A14: 34 | B14: Fights | C14: Fight screen, top right, farming | D14: Flag button (icon only) | E14: Tooltip | F14: End the run and keep everything it turned up | H14: =LEN(F14) -> 44 | I14: 5 | J14: 5 | K14: Keep | L14: Icon only, and the press ends the fight. It says so and takes away the fear of losing the loot. | N14: Scenes/Combat/combat_scene.gd | O14: 903
A15: 36 | B15: Fights | C15: Fight screen, top right, charting | D15: Flag button (icon only) | E15: Tooltip | F15: Give up the fight and keep what it already turned up | H15: =LEN(F15) -> 52 | I15: 5 | J15: 5 | K15: Keep | L15: Says it is a surrender and that the loot is safe. | N15: Scenes/Combat/combat_scene.gd | O15: 905
A16: 56 | B16: Bag | C16: A level's heading | D16: Struck-through chest (icon only, toggle) | E16: Tooltip | F16: Stop collecting level %d loot | G16: Stop collecting level 3 loot | H16: =LEN(F16) -> 29 | I16: 4 | J16: 5 | K16: Reword | L16: An icon with a lasting effect: every later drop of that level is thrown away. 'Stop collecting' is gentle for that, and 'level 3 loot' leaves 'item level' to be guessed. | M16: Leave level %d items where they fall from now on | N16: Scenes/UI/bag_page.gd | O16: 609
A17: 57 | B17: Bag | C17: A level's heading | D17: The same toggle, held down | E17: Tooltip | F17: Continue collecting level %d loot | G17: Continue collecting level 3 loot | H17: =LEN(F17) -> 33 | I17: 4 | J17: 5 | K17: Reword | L17: Clear as the way back. 'Continue' suggests it was only paused. | M17: Pick up level %d items again | N17: Scenes/UI/bag_page.gd | O17: 609
A18: 58 | B18: Bag | C18: A level's heading, in a town that buys gear | D18: Coins (icon only) | E18: Tooltip | F18: Sell %d level %d %s for %s gold | G18: Sell 7 level 3 items for 1.2K gold | H18: =LEN(F18) -> 31 | I18: 5 | J18: 5 | K18: Keep | L18: The count and the sum, before the press. Nothing else gives them. | N18: Scenes/UI/bag_page.gd | O18: 629
A19: 59 | B19: Bag | C19: A level's heading, away from town | D19: Bin (icon only) | E19: Tooltip | F19: Discard %d level %d %s | G19: Discard 7 level 3 items | H19: =LEN(F19) -> 22 | I19: 5 | J19: 5 | K19: Keep | L19: Says how many pieces the bin would take. | N19: Scenes/UI/bag_page.gd | O19: 630
A20: 61 | B20: Bag | C20: An open piece | D20: Equip button, when something comes off | E20: Tooltip | F20: , putting %s back in the bag | G20: Wear this in the weapon slot, putting Rusty Sword, Oak Shield back in the bag | H20: =LEN(F20) -> 28 | I20: 5 | J20: 5 | K20: Keep | L20: The only warning that a two-hander takes the offhand off as well. | N20: Scenes/UI/bag_page.gd | O20: 1090
A21: 62 | B21: Bag | C21: An open piece | D21: Equip button, greyed | E21: Tooltip: why a button is grey | F21: Needs %d %s | G21: Needs 12 Strength | H21: =LEN(F21) -> 11 | I21: 5 | J21: 5 | K21: Keep | L21: Short and exact. | N21: Scenes/Items/inventory.gd | O21: 517
A22: 63 | B22: Bag | C22: An open piece | D22: Equip button, greyed | E22: Tooltip: why a button is grey | F22: The bag is full | H22: =LEN(F22) -> 15 | I22: 3 | J22: 5 | K22: Reword | L22: Puzzling on Equip: why would putting something on need room? The room is for what comes off. | M22: No room in the bag for what comes off | N22: Scenes/Items/inventory.gd | O22: 508
A23: 64 | B23: Heirlooms | C23: An open heirloom | D23: Equip button, greyed | E23: Tooltip: why a button is grey | F23: Lone Heir: only one heirloom may be worn | H23: =LEN(F23) -> 40 | I23: 5 | J23: 5 | K23: Keep | L23: Names the curse and gives its rule. | N23: Scenes/Items/inventory.gd | O23: 510
A24: 66 | B24: Bag | C24: An open ring | D24: Swap button (icon only) | E24: Tooltip | F24: Equip over the other ring instead | H24: =LEN(F24) -> 33 | I24: 3 | J24: 5 | K24: Reword | L24: An icon with no word, and a press that does not equip: it changes which finger Equip will use. | M24: Switch Equip to the other ring slot | N24: Scenes/UI/bag_page.gd | O24: 1098
A25: 68 | B25: Bag | C25: An open piece, in a town that buys gear | D25: Sell button, greyed | E25: Tooltip: why a button is grey | F25: Never sell is on | H25: =LEN(F25) -> 16 | I25: 5 | J25: 5 | K25: Keep | L25: Names the exact switch to turn off, which sits on the same row. | N25: Scenes/UI/bag_page.gd | O25: 1108
A26: 70 | B26: Bag | C26: An open piece | D26: Never sell toggle, off | E26: Tooltip | F26: Sell all and the bin pass this by | H26: =LEN(F26) -> 33 | I26: 2 | J26: 5 | K26: Reword | L26: The only explanation of the padlock, and the hardest tooltip in the bag. 'Sell all' and 'the bin' are icons the player has never seen named, and 'pass this by' has to be decoded. It also leaves out that the piece's own Sell button goes grey. | M26: Keep this when a whole level is sold or discarded. It cannot be sold on its own either | N26: Scenes/UI/bag_page.gd | O26: 1132
A27: 71 | B27: Bag | C27: An open piece | D27: Never sell toggle, on | E27: Tooltip | F27: Let Sell all and the bin take this again | H27: =LEN(F27) -> 40 | I27: 2 | J27: 5 | K27: Reword | L27: The same problem from the other side. | M27: Allow this to be sold or discarded again | N27: Scenes/UI/bag_page.gd | O27: 1131
A28: 73 | B28: Bag | C28: An open worn piece | D28: Unequip button, greyed | E28: Tooltip: why a button is grey | F28: The bag is full | H28: =LEN(F28) -> 15 | I28: 5 | J28: 5 | K28: Keep | L28: The reason, and it is obvious what to do about it. | N28: Scenes/UI/bag_page.gd | O28: 1229
A29: 78 | B29: Transcension | C29: The bag, choosing an heirloom | D29: Make heirloom button, greyed | E29: Tooltip: why a button is grey | F29: Open the item you would keep | H29: =LEN(F29) -> 28 | I29: 4 | J29: 5 | K29: Keep | L29: Tells the player the step they have missed. | N29: Scenes/UI/bag_page.gd | O29: 1199
A30: 79 | B30: Transcension | C30: The bag, choosing an heirloom | D30: Make heirloom button, greyed | E30: Tooltip: why a button is grey | F30: This item is broken | H30: =LEN(F30) -> 19 | I30: 4 | J30: 5 | K30: Reword | L30: States a fact and leaves the rule to be guessed. | M30: A broken item cannot be made an heirloom | N30: Scenes/UI/bag_page.gd | O30: 1200
A31: 89 | B31: Orbs and runes | C31: Orb card (bag tray, loot list, vendor) | D31: Orb of Transmutation | E31: Hover card | F31: Makes an item uncommon with fresh modifiers, or rerolls an uncommon one's. | H31: =LEN(F31) -> 74 | I31: 2 | J31: 5 | K31: Reword | L31: The only explanation of the orb. It hides the catch: used on a rare or epic piece it makes that uncommon too. 'An uncommon one's' ends on a possessive with nothing after it, and 'rerolls' is never explained. | M31: Makes any item uncommon and gives it new modifiers. A rarer item drops to uncommon | N31: Scenes/Items/orb_table.gd | O31: 62
A32: 90 | B32: Orbs and runes | C32: Orb card (bag tray, loot list, vendor) | D32: Orb of Augmentation | E32: Hover card | F32: Adds one more modifier, at any rarity. | H32: =LEN(F32) -> 38 | I32: 2 | J32: 5 | K32: Reword | L32: 'At any rarity' is untrue for a common item, which the orb refuses, and it is unclear whether it describes the item or the modifier. It also does not say the item needs room. | M32: Adds one modifier to an item that has room for it. A common item has none | N32: Scenes/Items/orb_table.gd | O32: 66
A33: 91 | B33: Orbs and runes | C33: Orb card (bag tray, loot list, vendor) | D33: Orb of Alchemy | E33: Hover card | F33: Makes an item rare with fresh modifiers, or rerolls a rare one's. | H33: =LEN(F33) -> 65 | I33: 2 | J33: 5 | K33: Reword | L33: As Transmutation: an epic piece becomes rare, and the card does not warn of it. | M33: Makes any item rare and gives it new modifiers. An epic item drops to rare | N33: Scenes/Items/orb_table.gd | O33: 70
A34: 92 | B34: Orbs and runes | C34: Orb card (bag tray, loot list, vendor) | D34: Orb of Divinity | E34: Hover card | F34: Rerolls the value of every modifier, keeping the modifiers and their tiers. | H34: =LEN(F34) -> 75 | I34: 4 | J34: 5 | K34: Keep | L34: Exact, and says what is safe. It leans on 'tiers' and 'rerolls', which the game never explains. | N34: Scenes/Items/orb_table.gd | O34: 74
A35: 93 | B35: Orbs and runes | C35: Orb card (bag tray, loot list, vendor) | D35: Orb of Chaos | E35: Hover card | F35: Rerolls the tier and value of every modifier, keeping the modifiers themselves. | H35: =LEN(F35) -> 79 | I35: 4 | J35: 5 | K35: Keep | L35: Reads well beside Divinity: the two cards differ by exactly the word that matters. | N35: Scenes/Items/orb_table.gd | O35: 78
A36: 94 | B36: Orbs and runes | C36: Orb card (bag tray, loot list, vendor) | D36: Orb of Exaltation | E36: Hover card | F36: Makes an item epic with fresh modifiers, or rerolls an epic one's. | H36: =LEN(F36) -> 66 | I36: 3 | J36: 5 | K36: Reword | L36: No hidden catch here, since epic is the top. Only the dangling 'an epic one's'. | M36: Makes any item epic and gives it new modifiers | N36: Scenes/Items/orb_table.gd | O36: 82
A37: 97 | B37: Orbs and runes | C37: Rune card (bag tray) | D37: Rune of Shifting | E37: Hover card | F37: Rerolls the tiers of the modifiers runes gave a tile. | H37: =LEN(F37) -> 53 | I37: 2 | J37: 5 | K37: Reword | L37: 'The modifiers runes gave a tile' has to be read twice to find its verb. No rune card says how long its work lasts, or that the tile must be charted. | M37: Rolls new tiers for the modifiers that runes have added to a tile | N37: Scenes/Items/rune_table.gd | O37: 22
A38: 98 | B38: Orbs and runes | C38: Rune card (bag tray) | D38: Rune of Upheaval | E38: Hover card | F38: Rerolls the modifiers runes gave a tile into different ones. | H38: =LEN(F38) -> 60 | I38: 2 | J38: 5 | K38: Reword | L38: The same knot as Shifting. | M38: Swaps the modifiers that runes have added to a tile for different ones | N38: Scenes/Items/rune_table.gd | O38: 24
A39: 99 | B39: Orbs and runes | C39: Rune card (bag tray) | D39: Rune of Unrest | E39: Hover card | F39: Gives a tile a new modifier. | H39: =LEN(F39) -> 28 | I39: 4 | J39: 5 | K39: Keep | L39: Short and true. No rune card says how long its work lasts, or that the tile must be charted. | N39: Scenes/Items/rune_table.gd | O39: 26
A40: 100 | B40: Orbs and runes | C40: Rune card (bag tray) | D40: Rune of Stillness | E40: Hover card | F40: Takes away a modifier a rune gave a tile. | H40: =LEN(F40) -> 41 | I40: 3 | J40: 5 | K40: Reword | L40: Clear once parsed. It does not say which modifier goes when there are several. | M40: Removes one modifier that a rune added to a tile | N40: Scenes/Items/rune_table.gd | O40: 28
...

Sheet Developer only
A1: # | B1: Where it shows | C1: On | D1: Text | E1: File | F1: Line
A2: 1 | B2: Settings foot (debug builds) | C2: Developer button | D2: Dev: the tools a release build has none of | E2: Scenes/UI/settings_page.gd | F2: 395
A3: 2 | B3: Developer screen | C3: Show all uniques tick | D3: The collection log draws every unique as found | E3: Scenes/UI/settings_page.gd | F3: 496
A4: 3 | B4: Developer screen | C4: Show all chests tick | D4: Every chest is drawn on the map, fog or not | E4: Scenes/UI/settings_page.gd | F4: 500
A5: 4 | B5: Developer screen | C5: Show old icons tick | D5: An item whose icon was replaced wears its old one, from the next time it is drawn | E5: Scenes/UI/settings_page.gd | F5: 504
A6: 5 | B6: Developer screen | C6: Show all services tick | D6: Every settlement offers every counter, from the next time one is entered | E6: Scenes/UI/settings_page.gd | F6: 507
A7: 6 | B7: Developer screen | C7: Even loot tick | D7: A body drops loot one time in three, every rarity from common to unique as likely, from the next fight | E7: Scenes/UI/settings_page.gd | F7: 511
A8: 7 | B8: Developer screen | C8: Unlock Banish tick | D8: The fortuneteller offers Banish however few uniques are unlocked, from the next time her tab is opened | E8: Scenes/UI/settings_page.gd | F8: 514
A9: 8 | B9: Developer screen | C9: Gold x10 button | D9: Multiply your gold by ten | E9: Scenes/UI/settings_page.gd | F9: 516
A10: 9 | B10: Developer screen | C10: Skill points +10 button | D10: Ten levels, and the ten skill points they earn | E10: Scenes/UI/settings_page.gd | F10: 517
A11: 10 | B11: Developer screen | C11: Balancing button | D11: Scale enemy health wall by wall | E11: Scenes/UI/settings_page.gd | F11: 519
A12: 11 | B12: Developer screen | C12: Item generator button | D12: Make an item to order | E12: Scenes/UI/settings_page.gd | F12: 521
A13: 12 | B13: Developer screen | C13: Back arrow | D13: Back to the settings | E13: Scenes/UI/settings_page.gd | F13: 494
... A20: 19 | B20: Item generator | C20: Add to bag, greyed | D20: The bag is full | E20: Scenes/UI/item_generator.gd | F20: 161

Sheet Patterns
A1: Habit | B1: Where it shows | C1: What to do
A2: The best tooltips say what the press changes | B2: Farm ('for as long as you like, for the loot'), Restock ('Each time costs twice the last'), the attribute chips, Detailed item descriptions (with an example), the level heading's 'Sell 7 level 3 items for 1.2K gold', Sign out ('keeps its save'), Armour ('18% off every blow'). | C2: Use these as the pattern: a consequence, a number or a reassurance the button's own word cannot carry.
A3: Some two dozen only repeat their button | B3: 'Take this one' on Take, 'Give this bounty up' on Give up, 'Walk to the selected tile' on Move here, 'Take this work on' on Accept, 'Read the board again' on Refresh, and 'Close the ...' on every X. | C3: Cut them, or give each the one fact the button leaves out (as 'Stop on the next tile' does for Stop). Filter Verdict = Cut for the list.
A4: Some tooltips can never be seen | B4: Every item square ignores the mouse so that the grid under it can be dragged, and the tip card only reads what the mouse is on. Lost with it: the doll's socket names, 'Iron Greatsword takes both hands', a bounty's promised piece in words, 'Bought. Restock fills the shelf again'. The save error panel's 'Quit' is built before the tip card exists. | C4: Filter Kind = Never shown. Five are worth rescuing (Verdict = Never shows). The rest are covered by the item card and can stay as they are.
A5: An orb's sentence leaves out its catch | B5: Transmutation and Alchemy lower a rarer item and do not say so. Augmentation says 'at any rarity' and refuses a common item. The smith's Lock picks its modifier at random and the tooltip says only 'Pin one of its modifiers'. No rune card says how long its work lasts. | C5: These are the only explanations the game gives, and each is spent on something the player cannot undo. Say the catch first.
A6: One thing, several words | B6: Lock (the button), pin (its tooltip), bind (the super orb) and Never sell (the bag's padlock). Bounty, posting and 'work'. 'Spent here' and 'Already bought here' for the same once-a-town rule. 'Turned up', 'found' and 'collect' for loot. 'Out of the fog' where every other game says reveal. | C6: Pick one word for each and use it on the button and in its tooltip alike.
A7: Words the player has never been given | B7: 'Sell all' and 'the bin' are icons with no name on screen, yet the Never sell tooltip is written in them. 'The handful', 'the drop pool', 'reroll', 'tier', 'ascended', 'the choice', 'a skull for your curses'. | C7: Either name the thing where it stands, or describe it in the tooltip ('when a whole level is sold or discarded').
A8: A few are out of date | B8: Sign in says 'Put your descents on the board' and there are three boards. Collect says 'Take it all back to the map' and loot is already in the bag. The Abilities unlock describes something not built. An orb spent to nothing reads 'Not found yet'. | C8: Filter Verdict = Check.
A9: Grey buttons nearly always say why, which is right | B9: Equip, Unequip, Buy, Claim, Restock, the smith's two, every spell, Chart and Farm all give the reason, and most say what to do about it ('Open an item in your bag'). | C9: Three still do not: the skill tree's Reset, the leaderboard's Choose name under three letters, and Make heirloom on a broken piece (it states the fact, not the rule). Banish stays silent by your ruling of 2026-10-10.
A10: Where a tooltip is missing | B10: The character page's rows say where a number comes from and when it is capped, never what the stat does. Recoup, Time on Hit, Bleed, Elite Chance and most of the others have an empty tooltip. | C10: The Armour and Dodge rows show the way: one short line that turns the stat into what happens in a fight.
