Workbook

Sheet About
A1: Kobold Clicker: every tooltip, rated
A2: Exported | B2: 2026-10-10, from the working tree (branch dialogue-voices). Second pass: only a tooltip the player needs is kept.
A4: Sheets
A5: Tooltips | B5: Every tooltip a player can meet, one row each, with two ratings, a verdict and, for a kept one that reads badly, a rewrite. Filter by Area, Kind or Verdict.
A6: Developer only | B6: The tooltips of the developer screens, which a release build does not have. Listed, not rated.
A7: Patterns | B7: The rule the verdicts follow, what the cuts are made of, and what to watch for when cutting.
A9: Counts
A10: Rows | B10: =COUNTA(Tooltips!F2:F217) -> 216
A11: Keep | B11: =COUNTIF(Tooltips!K2:K217,"Keep") -> 45
A12: Reword (kept, with new words) | B12: =COUNTIF(Tooltips!K2:K217,"Reword") -> 43
A13: Cut | B13: =COUNTIF(Tooltips!K2:K217,"Cut") -> 128
A14: Share of tooltips the game needs | B14: =ROUND((COUNTIF(Tooltips!K2:K217,"Keep")+COUNTIF(Tooltips!K2:K217,"Reword"))/COUNTA(Tooltips!F2:F217),2) -> 0.41
A15: Needed, and explains poorly (Explains 1-3) | B15: =COUNTIFS(Tooltips!J2:J217,">=4",Tooltips!I2:I217,"<=3") -> 32
A16: Average: Explains | B16: =ROUND(AVERAGE(Tooltips!I2:I217),1) -> 4.2
A17: Average: Needed | B17: =ROUND(AVERAGE(Tooltips!J2:J217),1) -> 3.2
A18: On a control that cannot show it (Kind = Never shown) | B18: =COUNTIF(Tooltips!E2:E217,"Never shown") -> 9
A20: The rule for keeping | B20: A tooltip is kept only if the player needs it and the screen cannot say it. Needed 4 or 5 is kept, 3 or under is cut.
A22: Needed (1-5) | B22: How much the player would lose without it.
A23: 5 | B23: A rule, a cost or a consequence the player needs before the press, said nowhere else. Or the only explanation of a thing.
A24: 4 | B24: The only words for a control whose picture does not say what it does, or the only reason for a dead button whose cause is not on screen.
A25: 3 | B25: The player finds out by pressing, at no cost, or by reading the screen with a little thought.
A26: 2 | B26: The screen already says it: the button's own words, a heading, a price, the question after the press.
A27: 1 | B27: Repeats the control word for word, or can never be seen.
A29: Explains (1-5) | B29: How well the words explain the thing they are on.
A30: 5 | B30: Says exactly what the press or the thing does, in plain words.
A31: 4 | B31: Clear, with a small wobble: an odd word, a missing detail.
A32: 3 | B32: Understood on a second read, or leaves out something the player needs.
A33: 2 | B33: Likely to be misread, or leans on a word the game has not explained.
A34: 1 | B34: Does not explain, or says something untrue.
A36: Verdict
A37: Keep | B37: Needed, and it does its job.
A38: Reword | B38: Needed, and the wording gets in its way. A rewrite is offered.
A39: Cut | B39: Not needed. The Why column says what already tells the player.
A41: How to read a row
A42: Kind | B42: Tooltip: the cream tip card that comes up after half a second on a control. Tooltip: why a button is grey: the same card, on a dead button. Hover card: the sentence on an orb's, rune's or super orb's card. Never shown: text set as a tooltip that no card can show.
A43: Text | B43: As it is in the source. %d, %s and %.1f stand for a number or a name filled in as the game runs, and %% is a percent sign.
A44: Example, as shown | B44: The text with made-up numbers and names filled in, to show how it reads. The figures are not the game's.
A45: Suggested rewrite | B45: Only for a Reword. A proposal that keeps the rule as the code has it. Check the facts before using one.
A46: Read by | B46: What else in the project reads the text: code that builds on it, and tests that find a button by it or check its words. A cut or a rewrite has to be followed there.
A47: Line | B47: Where the text sits in the file. Several numbers mean it is written there more than once.
...

Sheet Tooltips
A1: # | B1: Area | C1: Where it shows | D1: On | E1: Kind | F1: Text | G1: Example, as shown | H1: Length | I1: Explains (1-5) | J1: Needed (1-5) | K1: Verdict | L1: Why | M1: Suggested rewrite | N1: File | O1: Line | P1: Read by
A2: 1 | B2: Map and main screen | C2: Corner buttons | D2: Star button (icon only), key K | E2: Tooltip | F2: Skill tree | H2: =LEN(F2) -> 10 | I2: 5 | J2: 4 | K2: Keep | L2: A star does not say skill tree. Of the corner's nine, one of the four whose picture needs the word. | N2: Scenes/main_scene.gd | O2: 970 | P2: Scenes/main_scene.gd:1047 (the Controls screen's list)
A3: 2 | B3: Map and main screen | C3: Corner buttons | D3: Chest button (icon only), key I | E3: Tooltip | F3: Items | H3: =LEN(F3) -> 5 | I3: 5 | J3: 3 | K3: Cut | L3: A chest reads as the bag, and one press shows it. Two things to know before cutting: the card also shows the page's key, and the Controls screen builds its list from this text, so the word stays in the code either way. | N3: Scenes/main_scene.gd | O3: 973 | P3: Scenes/main_scene.gd:1047 (the Controls screen's list)
A4: 3 | B4: Map and main screen | C4: Corner buttons | D4: Scroll button (icon only), key J | E4: Tooltip | F4: Bounties | H4: =LEN(F4) -> 8 | I4: 5 | J4: 4 | K4: Keep | L4: A scroll could be many things. The name settles it. | N4: Scenes/main_scene.gd | O4: 976 | P4: Scenes/main_scene.gd:1047 (the Controls screen's list)
A5: 4 | B5: Map and main screen | C5: Corner buttons | D5: Cog button (icon only), key O | E5: Tooltip | F5: Settings | H5: =LEN(F5) -> 8 | I5: 5 | J5: 2 | K5: Cut | L5: A cog is understood everywhere. Two things to know before cutting: the card also shows the page's key, and the Controls screen builds its list from this text, so the word stays in the code either way. | N5: Scenes/main_scene.gd | O5: 979 | P5: Scenes/main_scene.gd:1047 (the Controls screen's list)
A6: 5 | B6: Map and main screen | C6: Corner buttons | D6: Book button (icon only), key L | E6: Tooltip | F6: Collection | H6: =LEN(F6) -> 10 | I6: 4 | J6: 4 | K6: Keep | L6: A book does not say what is collected. The name at least says a collection. | N6: Scenes/main_scene.gd | O6: 982 | P6: Scenes/main_scene.gd:1047 (the Controls screen's list)
A7: 6 | B7: Map and main screen | C7: Corner buttons | D7: Trophy button (icon only), key Y | E7: Tooltip | F7: Achievements | H7: =LEN(F7) -> 12 | I7: 5 | J7: 3 | K7: Cut | L7: A trophy says it. Two things to know before cutting: the card also shows the page's key, and the Controls screen builds its list from this text, so the word stays in the code either way. | N7: Scenes/main_scene.gd | O7: 985 | P7: Scenes/main_scene.gd:1047 (the Controls screen's list)
A8: 7 | B8: Map and main screen | C8: Corner buttons | D8: Podium button (icon only), key P | E8: Tooltip | F8: Leaderboard | H8: =LEN(F8) -> 11 | I8: 5 | J8: 3 | K8: Cut | L8: A podium says it, and one press shows it. Two things to know before cutting: the card also shows the page's key, and the Controls screen builds its list from this text, so the word stays in the code either way. | N8: Scenes/main_scene.gd | O8: 988 | P8: Scenes/main_scene.gd:1047 (the Controls screen's list)
A9: 8 | B9: Map and main screen | C9: Corner buttons | D9: Crown button (icon only), key H | E9: Tooltip | F9: Heirlooms | H9: =LEN(F9) -> 9 | I9: 4 | J9: 4 | K9: Keep | L9: A crown does not say heirloom. | N9: Scenes/main_scene.gd | O9: 991 | P9: Scenes/main_scene.gd:1047 (the Controls screen's list)
A10: 9 | B10: Map and main screen | C10: Corner panel | D10: The hero's portrait panel, key C | E10: Tooltip | F10: Character | H10: =LEN(F10) -> 9 | I10: 5 | J10: 3 | K10: Cut | L10: The panel lights under the mouse and one press shows what it opens. Two things to know before cutting: the card also shows the page's key, and the Controls screen builds its list from this text, so the word stays in the code either way. | N10: Scenes/main_scene.gd | O10: 1009 | P10: Scenes/main_scene.gd:1047 (the Controls screen's list)
A11: 10 | B11: Map and main screen | C11: Corner panel | D11: Experience bar | E11: Tooltip | F11: %s / %s XP | G11: 120 / 450 XP | H11: =LEN(F11) -> 10 | I11: 5 | J11: 3 | K11: Cut | L11: The character page, one press away, writes the same line under its own bar. | N11: Scenes/UI/character_panel.gd | O11: 290 | P11: tests/test_ui_theme.gd:759
A12: 11 | B12: Map and main screen | C12: Map edge | D12: The hero's badge (portrait and arrow) | E12: Tooltip | F12: Find the hero | H12: =LEN(F12) -> 13 | I12: 4 | J12: 3 | K12: Cut | L12: The hero's face with an arrow, pressed at no cost. It shows what it does. | N12: Scenes/main_scene.gd | O12: 790
A13: 12 | B13: Map and main screen | C13: Map foot, while walking | D13: Stop button | E13: Tooltip | F13: Stop on the next tile | H13: =LEN(F13) -> 21 | I13: 5 | J13: 3 | K13: Cut | L13: The word is on the button, and the hero is seen to stop a tile on. | N13: Scenes/main_scene.gd | O13: 793
A14: 13 | B14: Map and main screen | C14: Tile panel | D14: X on the title bar | E14: Tooltip | F14: Close and deselect the tile | H14: =LEN(F14) -> 27 | I14: 5 | J14: 2 | K14: Cut | L14: An X is an X. | N14: Scenes/main_scene.gd | O14: 800
A15: 14 | B15: Map and main screen | C15: Tile panel | D15: Chart button | E15: Tooltip | F15: Fight for this tile and what lies behind it | H15: =LEN(F15) -> 43 | I15: 3 | J15: 5 | K15: Reword | L15: Chart is the game's own verb and this is the only place it is defined. 'What lies behind it' is the vague part: winning lifts the fog off the tile and the land in sight of it. | M15: Fight for this tile. Win, and it and the land around it come out of the fog | N15: Scenes/main_scene.gd | O15: 1955
A16: 15 | B16: Map and main screen | C16: Tile panel | D16: Farm button | E16: Tooltip | F16: Fight here for as long as you like, for the loot | H16: =LEN(F16) -> 48 | I16: 5 | J16: 4 | K16: Keep | L16: The only statement that this fight has no end and wins no land, only loot. | N16: Scenes/main_scene.gd | O16: 1956
A17: 16 | B17: Map and main screen | C17: Tile panel | D17: Chart and Farm, greyed | E17: Tooltip: why a button is grey | F17: Your bag is too heavy to fight with. Sell or discard gear until it holds %d or fewer | G17: Your bag is too heavy to fight with. Sell or discard gear until it holds 40 or fewer | H17: =LEN(F17) -> 84 | I17: 4 | J17: 5 | K17: Reword | L17: The only place the reason and the limit are said, and it says how to fix it. Two wobbles: nothing else in the game weighs anything (elsewhere the bag is 'full'), and 'or fewer' has no noun. | M17: Your bag is over its limit. Sell or discard gear until it holds %d items or fewer | N17: Scenes/main_scene.gd | O17: 1959 | P17: tests/test_inventory_saving.gd:830
A18: 17 | B18: Map and main screen | C18: Tile panel | D18: Move here button | E18: Tooltip | F18: Walk to the selected tile | H18: =LEN(F18) -> 25 | I18: 5 | J18: 2 | K18: Cut | L18: Says what the button's own words say. | N18: Scenes/main_scene.gd | O18: 852
A19: 18 | B19: Map and main screen | C19: Tile panel | D19: Enter town button | E19: Tooltip | F19: Go inside and see what is traded here | H19: =LEN(F19) -> 37 | I19: 5 | J19: 2 | K19: Cut | L19: Repeats the button. The services are listed in the panel above it. | N19: Scenes/main_scene.gd | O19: 866
A20: 19 | B20: Map and main screen | C20: Tile panel, on the cave | D20: Enter cave button | E20: Tooltip | F20: Go down to depth %d. Kill Gollux to go deeper: each depth won is a skull for your curses | G20: Go down to depth 3. Kill Gollux to go deeper: each depth won is a skull for your curses | H20: =LEN(F20) -> 88 | I20: 3 | J20: 5 | K20: Reword | L20: Carries the whole rule of the cave, and nothing else on the panel does. The last part is hard: 'a skull for your curses' only means something to a player who has already seen the curse table. | M20: Go down to depth %d. Kill Gollux to win the depth. Each depth won gives one more skull to spend on curses | N20: Scenes/main_scene.gd | O20: 2438 | P20: tests/test_combat_curses.gd:613, 654
A21: 20 | B21: Map and main screen | C21: Ice wall's tile panel: Unlocks | D21: An orb's row (walls 1 and 2) | E21: Tooltip | F21: (the orb's own description, as on its card) | H21: =LEN(F21) -> 43 | I21: 3 | J21: 3 | K21: Cut | L21: A teaser on the wall's panel for a thing that explains itself when it is met. The orb's card says this the moment one drops. | N21: Scenes/Items/wall_unlocks.gd | O21: 59
A22: 21 | B22: Map and main screen | C22: Ice wall's tile panel: Unlocks | D22: Gollux row (wall 3) | E22: Tooltip | F22: His cave appears in every world | H22: =LEN(F22) -> 31 | I22: 3 | J22: 3 | K22: Cut | L22: A teaser on the wall's panel for a thing that explains itself when it is met. The red light, the hero's line and Enter cave teach Gollux. The bare name does the teasing better. | N22: Scenes/Items/wall_unlocks.gd | O22: 28
A23: 22 | B23: Map and main screen | C23: Ice wall's tile panel: Unlocks | D23: Runes row (wall 3) | E23: Tooltip | F23: Dropped in Gollux's cave, they give a charted tile modifiers | H23: =LEN(F23) -> 60 | I23: 3 | J23: 3 | K23: Cut | L23: A teaser on the wall's panel for a thing that explains itself when it is met. The first rune drops in the cave with a card of its own. | N23: Scenes/Items/wall_unlocks.gd | O23: 30
A24: 23 | B24: Map and main screen | C24: Ice wall's tile panel: Unlocks | D24: Distant charting row (wall 4) | E24: Tooltip | F24: Chart any tile you can see, fighting for every tile on the way | H24: =LEN(F24) -> 62 | I24: 5 | J24: 5 | K24: Keep | L24: Nothing in the world announces this unlock, so this line is its only explanation. The whole rule, cost included. | N24: Scenes/Items/wall_unlocks.gd | O24: 32
A25: 24 | B25: Map and main screen | C25: Ice wall's tile panel: Unlocks | D25: Item filter row (wall 6) | E25: Tooltip | F25: Leave behind the loot you do not want | H25: =LEN(F25) -> 37 | I25: 4 | J25: 5 | K25: Reword | L25: Nothing in the world announces this unlock. It says what the filter does and not where it is, and nothing points to Settings. | M25: Leave behind the loot you do not want. Set it in Settings | N25: Scenes/Items/wall_unlocks.gd | O25: 34
A26: 25 | B26: Map and main screen | C26: Ice wall's tile panel: Unlocks | D26: Abilities row (wall 7) | E26: Tooltip | F26: Skill nodes that put a button in the fight | H26: =LEN(F26) -> 42 | I26: 3 | J26: 3 | K26: Cut | L26: A teaser on the wall's panel for a thing that explains itself when it is met. It is also for something not built: nothing in the code uses the Abilities unlock yet. | N26: Scenes/Items/wall_unlocks.gd | O26: 36
A27: 26 | B27: Map and main screen | C27: Ice wall's tile panel: Unlocks | D27: Skill branch row (walls 3, 5, 8 and on) | E27: Tooltip | F27: The skill tree's root takes %d more node%s | G27: The skill tree's root takes 1 more node | H27: =LEN(F27) -> 42 | I27: 3 | J27: 2 | K27: Cut | L27: Says the row's own name ('+1 skill branch') again, with a second word, node, for the same thing. | N27: Scenes/Items/wall_unlocks.gd | O27: 66
A28: 27 | B28: Map and main screen | C28: A cleared board's reward (pick 1 of 3) | D28: An orb among the three | E28: Tooltip | F28: (the orb's own description, as on its card) | H28: =LEN(F28) -> 43 | I28: 3 | J28: 4 | K28: Keep | L28: A choice that cannot be taken back, and only the orb's name is written under it. | N28: Scenes/main_scene.gd | O28: 1555
A29: 28 | B29: Map and main screen | C29: A cleared board's reward (pick 1 of 3) | D29: Take button | E29: Tooltip | F29: Take this one | H29: =LEN(F29) -> 13 | I29: 5 | J29: 1 | K29: Cut | L29: Says what the button's own words say. | N29: Scenes/main_scene.gd | O29: 1567
A30: 29 | B30: Map and main screen | C30: A cleared board's reward (pick 1 of 3) | D30: Take button, greyed | E30: Tooltip: why a button is grey | F30: Nothing to take | H30: =LEN(F30) -> 15 | I30: 3 | J30: 1 | K30: Cut | L30: A safety answer the player cannot reach. | N30: Scenes/UI/town_page.gd | O30: 820
A31: 30 | B31: Map and main screen | C31: Bounty reward pop-up | D31: Collect button | E31: Tooltip | F31: Put it all away | H31: =LEN(F31) -> 15 | I31: 3 | J31: 2 | K31: Cut | L31: Says what the button's own words say. | N31: Scenes/main_scene.gd | O31: 1440
A32: 31 | B32: Map and main screen | C32: Banners (achievement, new unique) | D32: X on the banner | E32: Tooltip | F32: Close | H32: =LEN(F32) -> 5 | I32: 5 | J32: 1 | K32: Cut | L32: An X is an X. | N32: Scenes/main_scene.gd | O32: 1357
A33: 32 | B33: Map and main screen | C33: Save error panel | D33: X on the title bar | E33: Never shown | F33: Quit | H33: =LEN(F33) -> 4 | I33: 5 | J33: 1 | K33: Cut | L33: Never seen: the panel is built before the tip card exists. Nothing is lost, since there is no game behind the panel for the X to close onto. | N33: Scenes/main_scene.gd | O33: 696
A34: 33 | B34: Fights | C34: Fight screen, bottom right | D34: Sack button (icon and a count) | E34: Tooltip | F34: What this run has turned up | H34: =LEN(F34) -> 27 | I34: 4 | J34: 3 | K34: Cut | L34: The count on its face says what it is, and a press opens a panel headed Loot. | N34: Scenes/Combat/combat_scene.gd | O34: 930
A35: 34 | B35: Fights | C35: Fight screen, top right, farming | D35: Flag button (icon only) | E35: Tooltip | F35: End the run and keep everything it turned up | H35: =LEN(F35) -> 44 | I35: 5 | J35: 4 | K35: Keep | L35: A bare flag whose press ends the run. It also takes away the fear of losing the loot. | N35: Scenes/Combat/combat_scene.gd | O35: 953
A36: 35 | B36: Fights | C36: Fight screen, top right, in the cave | D36: Flag button (icon only) | E36: Tooltip | F36: End the descent here | H36: =LEN(F36) -> 20 | I36: 4 | J36: 4 | K36: Keep | L36: A bare flag whose press ends the descent. Finding out by pressing costs the descent. | N36: Scenes/Combat/combat_scene.gd | O36: 954
A37: 36 | B37: Fights | C37: Fight screen, top right, charting | D37: Flag button (icon only) | E37: Tooltip | F37: Give up the fight and keep what it already turned up | H37: =LEN(F37) -> 52 | I37: 5 | J37: 5 | K37: Keep | L37: A bare flag whose press loses the fight. Finding out by pressing costs the tile. | N37: Scenes/Combat/combat_scene.gd | O37: 955
A38: 37 | B38: Fights | C38: Fight result, won | D38: Collect button | E38: Tooltip | F38: Take it all back to the map | H38: =LEN(F38) -> 27 | I38: 3 | J38: 2 | K38: Cut | L38: Repeats the button, and is out of date: loot goes into the bag as it drops. | N38: Scenes/Combat/combat_scene.gd | O38: 1056
A39: 38 | B39: Fights | C39: Fight result, lost | D39: Back arrow (icon only) | E39: Tooltip | F39: Back to the map | H39: =LEN(F39) -> 15 | I39: 5 | J39: 2 | K39: Cut | L39: The arrow says it, as you ruled for the banishing's arrow on 2026-10-10. | N39: Scenes/Combat/combat_scene.gd | O39: 1063
... A44: 43 | B44: Camp | C44: Camp report | D44: X on the title bar, and Break camp | E44: Tooltip | F44: Go back to the map | H44: =LEN(F44) -> 18 | I44: 5 | J44: 2 | K44: Cut | L44: The X and Break camp are the only way on, and a press is the only thing to do. | N44: Scenes/Combat/camp_scene.gd | O44: 62, 102
...

Sheet Developer only
A1: # | B1: Where it shows | C1: On | D1: Text | E1: File | F1: Line
A2: 1 | B2: Settings foot (debug builds) | C2: Developer button | D2: Dev: the tools a release build has none of | E2: Scenes/UI/settings_page.gd | F2: 395
A3: 2 | B3: Developer screen | C3: Show all uniques tick | D3: The collection log draws every unique as found | E3: Scenes/UI/settings_page.gd | F3: 496
A4: 3 | B4: Developer screen | C4: Show all chests tick | D4: Every chest is drawn on the map, fog or not | E4: Scenes/UI/settings_page.gd | F4: 500
A5: 4 | B5: Developer screen | C5: Show old icons tick | D5: An item whose icon was replaced wears its old one, from the next time it is drawn | E5: Scenes/UI/settings_page.gd | F5: 504
A6: 5 | B6: Developer screen | C6: Show all services tick | D6: Every settlement offers every counter, from the next time one is entered | E6: Scenes/UI/settings_page.gd | F6: 507
A7: 6 | B7: Developer screen | C7: Even loot tick | D7: A body drops loot one time in three, every rarity from common to unique as likely, from the next fight | E7: Scenes/UI/settings_page.gd | F7: 511
A8: 7 | B8: Developer screen | C8: Unlock Banish tick | D8: The fortuneteller offers Banish however few uniques are unlocked, from the next time her tab is opened | E8: Scenes/UI/settings_page.gd | F8: 514
A9: 8 | B9: Developer screen | C9: Gold x10 button | D9: Multiply your gold by ten | E9: Scenes/UI/settings_page.gd | F9: 516
A10: 9 | B10: Developer screen | C10: Skill points +10 button | D10: Ten levels, and the ten skill points they earn | E10: Scenes/UI/settings_page.gd | F10: 517
A11: 10 | B11: Developer screen | C11: Balancing button | D11: Scale enemy health wall by wall | E11: Scenes/UI/settings_page.gd | F11: 519
A12: 11 | B12: Developer screen | C12: Item generator button | D12: Make an item to order | E12: Scenes/UI/settings_page.gd | F12: 521
A13: 12 | B13: Developer screen | C13: Back arrow | D13: Back to the settings | E13: Scenes/UI/settings_page.gd | F13: 494
... A20: 19 | B20: Item generator | C20: Add to bag, greyed | D20: The bag is full | E20: Scenes/UI/item_generator.gd | F20: 161

Sheet Patterns
A1: Habit | B1: Where it shows | C1: What to do
A2: The rule this pass keeps a tooltip by | B2: A tooltip stays only if the player needs it and the screen cannot say it. Four things earn one: a picture that does not say what the control does; a rule, cost or consequence needed before the press; the reason for a dead button when the cause is not on screen; the only explanation of a thing (an orb, a spell, an attribute). | C2: Everything else is cut. The counts are on the About sheet, and Verdict filters the list.
A3: What the cuts are made of | B3: Every X ('Close the ...'). Every arrow ('Back to ...'), by your own ruling on the banishing's arrow. Every button that has its word and its price on it (Buy, Sell, Unequip, Accept, Retry). Tabs whose mark a press explains at once (the bag's nine, the town's five). 'Not enough gold', by your ruling on Banish. Lines the question after the press says again (Reset save, Make heirloom, 'Keep which save?'). Breakdowns nothing is decided by (Base, Gear, Bare hands, Reached). | C3: Filter Verdict = Cut.
A4: The corner row is split, and you may not want it split | B4: Read one at a time, four of the nine need their word (star, scroll, book, crown) and five do not (chest, cog, trophy, podium, the portrait). But the card is also where each page's key is shown, and a row where some buttons answer the mouse and some do not reads as broken. | C4: Either follow the verdicts, or keep all nine for the key's sake. Not a middle road.
A5: Cutting a tooltip can break something that reads it | B5: The Controls screen builds its list from the corner buttons' tooltips. The level heading's question is its tooltip with a question mark. About thirty lines in tests/ find a button by its tooltip or check its words. | C5: The Read by column names what reads each row. A cut button needs a node name for its test, as the banishing's Back got on 2026-10-10.
A6: Nine tooltips are dead text | B6: Every item square ignores the mouse so the grid under it can be dragged, and the tip card only reads what the mouse is on. So the socket names, 'takes both hands', a bounty's promised piece and 'Bought. Restock fills the shelf again' are never seen, nor is the save error panel's 'Quit', built before the tip card exists. | C6: None is needed: the picture, the frame or the item card says each. Filter Kind = Never shown.
A7: Half of what is kept needs new words | B7: Transmutation and Alchemy lower a rarer item and do not say so. Augmentation says 'at any rarity' and refuses a common item. The smith's Lock picks its modifier at random and says only 'Pin one of its modifiers'. Never sell is explained in the names of two icons. No rune card says how long its work lasts. | C7: These are the ones to spend the time on: each is the only explanation of something the player cannot undo. Filter Verdict = Reword.
A8: A dead button needs its reason only when the cause is off screen | B8: Needed: Chart and Farm under a full bag, Claim on a full bag, Equip short of an attribute, Accept while a bounty is out, the smith's level limit, every spell. Not needed: a short purse beside a price, Unequip on a full bag with the count beside it, the smith on a piece that says Broken, Sell beside a lit Never sell. | C8: Three dead buttons still say nothing and should: the skill tree's Reset, the leaderboard's Choose name under three letters, and Make heirloom, which states the fact and not the rule.
A9: One thing, several words | B9: Lock (the button), pin (its tooltip), bind (the super orb) and Never sell (the padlock). 'Spent here' and 'Already bought here' for the same once-a-town rule. 'Turned up' and 'found' for loot. 'Out of the fog' for reveal. | C9: Pick one word for each and use it on the button and in its tooltip alike.
A10: Words the player has never been given | B10: 'Sell all' and 'the bin' are icons with no name on screen. 'The drop pool', 'reroll', 'tier', 'ascended', 'a skull for your curses'. | C10: Describe the thing in the tooltip ('when a whole level is sold or discarded') rather than name it.
A11: Where a tooltip is owed and missing | B11: The character page's rows say when a number is capped and never what the stat does: Recoup, Time on Hit, Bleed and most of the others have nothing. Under this pass's own rule they are owed one. | C11: The Armour and Dodge rows show the way: one short line that turns the stat into what happens in a fight.
