Workbook

Sheet Summary
A1: PoE modifiers for Kobold Clicker
A2: Source: poedb.tw/us item-class pages (38 classes: weapons, armour by attribute, jewellery, quivers, jewels, flasks), read 2026-10-29: 44,968 tiers, 1,868 distinct modifiers.
A3: Item modifiers: picked and adapted by hand. N stands for the rolled number; bands are left to you.
A4: Tile & curse ideas: PoE map modifiers, written from the game (poedb draws its map lists in script).
A5: All poedb candidates: every modifier left after cutting what has no counterpart here (life, mana, resistances, elements, spells, minions, flasks, ...). 'Picked' marks those on the first tab.
A7: Fit | B7: Item modifiers | C7: Tile ideas | D7: Meaning
A8: In game | B8: =COUNTIF('Item modifiers'!$J:$J,A8) -> 21 | C8: =COUNTIF('Tile & curse ideas'!$D:$D,A8) -> 10 | D8: A line the game already rolls
A9: Variant | B9: =COUNTIF('Item modifiers'!$J:$J,A9) -> 10 | C9: =COUNTIF('Tile & curse ideas'!$D:$D,A9) -> 0 | D9: Close to an existing line or system
A10: New stat | B10: =COUNTIF('Item modifiers'!$J:$J,A10) -> 29 | C10: =COUNTIF('Tile & curse ideas'!$D:$D,A10) -> 0 | D10: A new stat on the existing systems
A11: New mechanic | B11: =COUNTIF('Item modifiers'!$J:$J,A11) -> 30 | C11: =COUNTIF('Tile & curse ideas'!$D:$D,A11) -> 0 | D11: Needs a new system (stacks, buffs, rage...)
A12: Unique idea | B12: =COUNTIF('Item modifiers'!$J:$J,A12) -> 9 | C12: =COUNTIF('Tile & curse ideas'!$D:$D,A12) -> 0 | D12: A rule-changer for a unique
A13: Drawback | B13: =COUNTIF('Item modifiers'!$J:$J,A13) -> 3 | C13: =COUNTIF('Tile & curse ideas'!$D:$D,A13) -> 0 | D13: A downside for a unique
A14: Future | B14: =COUNTIF('Item modifiers'!$J:$J,A14) -> 1 | C14: =COUNTIF('Tile & curse ideas'!$D:$D,A14) -> 4 | D14: Waits on something unbuilt
A15: New | B15: =COUNTIF('Item modifiers'!$J:$J,A15) -> 0 | C15: =COUNTIF('Tile & curse ideas'!$D:$D,A15) -> 13 | D15: A new tile modifier
A16: Total | B16: =SUM(B8:B15) -> 103 | C16: =SUM(C8:C15) -> 27

Sheet Item modifiers
A1: # | B1: Group | C1: PoE modifier (poedb) | D1: PoE top tier (poedb) | E1: PoE min item level | F1: PoE item classes | G1: PoE source | H1: Line for Kobold Clicker | I1: Reads / needs | J1: Fit | K1: Suggested piece | L1: Notes
A2: 1 | B2: Damage | C2: #% increased Physical Damage | D2: (170-179)% increased Physical Damage | E2: 1 | F2: Bows, Claws, Daggers, One Hand Axes, One Hand Maces, One Hand Swords, Sceptres, Staves, Two Hand Maces, Two Hand Swords, Wands | G2: Base, Corrupted, Crafting Bench, Synthesis | H2: +N% increased Damage | I2: damage (PERCENT) | J2: In game | K2: Weapon | L2: increased_damage
A3: 2 | B3: Damage | C3: Adds # to # Physical Damage | D3: Adds (22-29) to (45-52) Physical Damage | E3: 2 | F3: Bows, Claws, Daggers, Gloves, One Hand Axes, One Hand Maces, One Hand Swords, Sceptres, Staves, Two Hand Maces, Two Hand Swords, Wands | G3: Base, Corrupted, Crafting Bench, Delve, Essence, Scourge Beneficial, Synthesis | H3: +N Damage | I3: damage (FLAT) | J3: In game | K3: Weapon | L3: added_damage; PoE rolls a min-max pair, the game one number
A4: 3 | B4: Damage | C4: #% increased Damage | D4: (8-10)% increased Damage | E4: 1 | F4: Belts, Body Armours, Bows, Claws, Cobalt Jewel, Crimson Jewel, Daggers, One Hand Axes, One Hand Maces, One Hand Swords, Rings, Sceptres, Staves, Two Hand Maces, Two Hand Swords, Viridian Jewel, Wands | G4: Base, Corrupted, Crafting Bench, Synthesis | H4: +N% increased Damage (whole set) | I4: damage (GLOBAL) | J4: In game | K4: Ring, Amulet | L4: global_increased_damage
A5: 4 | B5: Damage | C5: #% chance to deal Double Damage | D5: (4-5)% chance to deal Double Damage | E5: 36 | F5: Bows, Claws, Daggers, One Hand Axes, One Hand Maces, One Hand Swords, Sceptres, Shields, Staves, Two Hand Maces, Two Hand Swords, Wands | G5: Crafting Bench, Delve, Synthesis | H5: N% chance a blow deals double damage | I5: new stat | J5: Variant | K5: Weapon, Amulet | L5: added_double_strike swings twice; this doubles one hit, and the bleed it seeds
A6: 5 | B6: Damage | C6: #% chance to deal Triple Damage | D6: 4% chance to deal Triple Damage | E6: 45 | F6: Bows, Claws, Daggers, One Hand Axes, One Hand Maces, One Hand Swords, Sceptres, Staves, Two Hand Maces, Two Hand Swords, Wands | G6: Scourge Beneficial | H6: N% chance a blow deals triple damage | I6: new stat | J6: New stat | K6: Weapon (late tiers) | L6: PoE gates it behind high item level: a deep tier of the line above
A7: 6 | B7: Damage | C7: #% increased Damage per # Strength | D7: 3% increased Damage per 100 Strength | E7: 60 | F7: Amulets, Gloves | G7: Synthesis, The Eater of Worlds | H7: +1% increased Damage per N Strength | I7: Inventory.attributes() | J7: New stat | K7: Amulet, Ring | L7: Dexterity and Intelligence versions on poedb too; gives points a use past the equip gate
A8: 7 | B8: Damage | C8: #% increased Damage with Two Handed Weapons | D8: (12-14)% increased Damage with Two Handed Weapons | E8: 1 | F8: Crimson Jewel, Viridian Jewel | G8: Base | H8: +N% increased Damage while wielding a two-handed weapon | I8: worn weapon | J8: New stat | K8: Ring, Amulet, Body | L8: A one-handed twin rewards sword, dagger and mace
A9: 8 | B9: Damage | C9: #% increased Damage with Swords | D9: (14-16)% increased Damage with Swords | E9: 1 | F9: Crimson Jewel, Viridian Jewel | G9: Base | H9: +N% increased Damage with a sword | I9: worn weapon kind | J9: New stat | K9: Ring, Amulet | L9: One line a kind: sword, dagger, mace, greatsword
A10: 9 | B10: Speed | C10: #% increased Attack Speed with Daggers | D10: (6-8)% increased Attack Speed with Daggers | E10: 1 | F10: Cobalt Jewel, Crimson Jewel, Viridian Jewel | G10: Base, Synthesis | H10: +N% increased Attack Speed with a dagger | I10: worn weapon kind | J10: New stat | K10: Ring, Boots | L10: One line a kind, as above
A11: 10 | B11: Damage | C11: #% increased Attack Damage while holding a Shield | D11: (12-14)% increased Attack Damage while holding a Shield | E11: 1 | F11: Crimson Jewel, Viridian Jewel | G11: Base | H11: +N% increased Damage while holding a shield | I11: worn offhand kind | J11: New stat | K11: Shield, Helmet | L11: Buckler and torch twins
A12: 11 | B12: Speed | C12: #% increased Attack Speed while holding a Shield | D12: (4-6)% increased Attack Speed while holding a Shield | E12: 1 | F12: Cobalt Jewel, Crimson Jewel, Viridian Jewel | G12: Base | H12: +N% increased Attack Speed while holding a buckler | I12: worn offhand kind | J12: New stat | K12: Buckler
A13: 12 | B13: Bleed | C13: Adds # to # Physical Damage against Bleeding Enemies | D13: Adds (7-11) to (12-18) Physical Damage against Bleeding Enemies | E13: 1 | F13: Gloves | G13: Delve | H13: +N Damage to bleeding enemies | I13: enemy bleeding | J13: New stat | K13: Mace | L13: Makes the mace's bleed pay twice
A14: 13 | B14: Bleed | C14: #% chance to cause Bleeding on Hit / #% increased Attack Damage against Bleeding Enemies | D14: 20% chance to cause Bleeding on Hit / (30-40)% increased Attack Damage against Bleeding Enemies | E14: 1 | F14: One Hand Axes | G14: Corrupted | H14: +N% increased Damage against bleeding enemies | I14: enemy bleeding | J14: New stat | K14: Mace, Ring | L14: A hybrid on poedb; one stat a line here
A15: 14 | B15: Damage | C15: Culling Strike | D15: Culling Strike | E15: 1 | F15: Bows, Claws, Daggers, One Hand Axes, One Hand Maces, One Hand Swords, Sceptres, Staves, Two Hand Maces, Two Hand Swords, Wands | G15: Scourge Beneficial | H15: Enemies left under N% health die at once | I15: new stat (cull) | J15: New mechanic | K15: Weapon, Amulet | L15: PoE's is a flat 10%; a 5-15% band cuts the slow last sliver of a big health bar
A16: 15 | B16: Damage | C16: #% increased Damage with Hits and Ailments against Abyssal Monsters | D16: (21-25)% increased Damage with Hits and Ailments against Abyssal Monsters | E16: 40 | F16: Bows, Claws, Daggers, Gloves, Helmets, One Hand Axes, One Hand Maces, One Hand Swords, Sceptres, Staves, Two Hand Maces, Two Hand Swords, Wands | G16: Synthesis | H16: +N% increased Damage in the <land> | I16: the tile's environment | J16: New stat | K16: Any piece | L16: One line per land (six); sits beside Homeland and the home uniques
A17: 16 | B17: Damage | C17: While a Unique Enemy is in your Presence, #% increased Attack Damage | D17: While a Unique Enemy is in your Presence, (29-31)% increased Attack Damage | E17: 75 | F17: Amulets, Helmets | G17: The Eater of Worlds | H17: +N% increased Damage against bosses | I17: boss flag (lairs) | J17: Variant | K17: Weapon, Helmet | L17: added_elite_damage covers elites and bosses together; this one is for lair farming
A18: 17 | B18: Damage | C18: #% increased Damage if Corrupted | D18: (15-20)% increased Damage if Corrupted | E18: 60 | F18: Rings | G18: Synthesis, Synthesis Corrupted | H18: +N% increased Damage while this piece is +1 or more | I18: Item ascension | J18: Variant | K18: Any piece | L18: PoE rewards a risky Vaal; ascension is this game's nearest
A19: 18 | B19: Damage | C19: #% chance to Impale Enemies on Hit with Attacks | D19: (5-7)% chance to Impale Enemies on Hit with Attacks | E19: 1 | F19: Cobalt Jewel, Crimson Jewel, Gloves, Rings, Viridian Jewel | G19: Base, Delve, Scourge Beneficial, Synthesis, The Eater of Worlds | H19: N% chance a blow impales: the enemy's next 5 hits take 10% of it again | I19: new enemy state | J19: New mechanic | K19: Sword, Greatsword | L19: Gives the sword line a mechanic of its own
A20: 19 | B20: Damage | C20: #% increased Impale Effect | D20: (22-25)% increased Impale Effect | E20: 45 | F20: Bows, Claws, Daggers, One Hand Axes, One Hand Maces, One Hand Swords, Sceptres, Staves, Two Hand Maces, Two Hand Swords | G20: Essence, Scourge Beneficial | H20: Impales store N% more damage | I20: impale | J20: New mechanic | K20: Ring | L20: Needs the impale above
A21: 20 | B21: Damage | C21: Skills Chain # times | D21: Skills Chain +1 times | E21: 68 | F21: Quivers | G21: Scourge Beneficial | H21: N% of a killing blow's leftover damage carries to the next enemy | I21: overkill | J21: New mechanic | K21: Weapon, Amulet | L21: Adapted far: a clicker's version of hitting more than one target
A22: 21 | B22: Crit | C22: #% increased Critical Strike Chance | D22: (35-38)% increased Critical Strike Chance | E22: 1 | F22: Bows, Claws, Daggers, One Hand Axes, One Hand Maces, One Hand Swords, Sceptres, Staves, Two Hand Maces, Two Hand Swords, Wands | G22: Base, Corrupted, Crafting Bench, Essence, Synthesis | H22: +N% increased Crit Chance | I22: crit_chance (PERCENT) | J22: In game | K22: Weapon | L22: increased_crit
A23: 22 | B23: Crit | C23: Attacks have #% to Critical Strike Chance | D23: Attacks have +(0.5-1)% to Critical Strike Chance | E23: 60 | F23: Body Armours, Gloves | G23: Corrupted, Synthesis | H23: +N% to Crit Chance | I23: crit_chance (FLAT) | J23: In game | K23: Weapon | L23: added_crit
A24: 23 | B24: Crit | C24: #% increased Global Critical Strike Chance | D24: (35-38)% increased Global Critical Strike Chance | E24: 1 | F24: Amulets, Belts, Cobalt Jewel, Crimson Jewel, Gloves, Helmets, Quivers, Rings, Viridian Jewel | G24: Base, Corrupted, Crafting Bench, Essence, Haunted Modifiers, Scourge Beneficial, Synthesis | H24: +N% increased Crit Chance (whole set) | I24: crit_chance (GLOBAL) | J24: In game | K24: Ring, Amulet | L24: global_increased_crit
A25: 24 | B25: Crit | C25: #% to Global Critical Strike Multiplier | D25: +(35-38)% to Global Critical Strike Multiplier | E25: 1 | F25: Amulets, Bows, Claws, Cobalt Jewel, Crimson Jewel, Daggers, Gloves, One Hand Axes, One Hand Maces, One Hand Swords, Quivers, Rings, Sceptres, Staves, Two Hand Maces, Two Hand Swords, Viridian Jewel, Wands | G25: Base, Corrupted, Crafting Bench, Essence, Haunted Modifiers, Scourge Beneficial, Synthesis | H25: +N% to Crit Damage | I25: crit_damage | J25: In game | K25: Weapon, Ring, Amulet | L25: added_crit_damage, global_increased_crit_damage
A26: 25 | B26: Crit | C26: #% Critical Strike Multiplier while a Rare or Unique Enemy is Nearby | D26: +(26-30)% Critical Strike Multiplier while a Rare or Unique Enemy is Nearby | E26: 60 | F26: Bows, Claws, Daggers, One Hand Axes, One Hand Maces, One Hand Swords, Sceptres, Staves, Two Hand Maces, Two Hand Swords, Wands | G26: Crafting Bench | H26: +N% to Crit Damage against elites and bosses | I26: elite flag | J26: New stat | K26: Helmet, Amulet
A27: 26 | B27: Unique idea | C27: Resolute Technique | D27: Resolute Technique | E27: 40 | F27: Body Armours, One Hand Swords, Two Hand Swords | G27: Corrupted, Recombinator, Scourge Beneficial | H27: Never crits; +N% more Damage | I27: keystone | J27: Unique idea | K27: A unique | L27: A build-around for the crit-less
A28: 27 | B28: Drawback | C28: Your Critical Strikes do not deal extra Damage | D28: Your Critical Strikes do not deal extra Damage | E28: 45 | F28: Amulets | G28: Scourge Detrimental | H28: Crits deal no extra damage | I28: keystone | J28: Drawback | K28: A unique | L28: Pairs with on-crit effects (stacks, stun) on the same unique
A29: 28 | B29: Speed | C29: #% increased Attack Speed | D29: (26-27)% increased Attack Speed | E29: 1 | F29: Amulets, Bows, Claws, Cobalt Jewel, Crimson Jewel, Daggers, Gloves, One Hand Axes, One Hand Maces, One Hand Swords, Quivers, Rings, Sceptres, Shields, Staves, Two Hand Maces, Two Hand Swords, Viridian Jewel, Wands | G29: Base, Corrupted, Crafting Bench, Essence, Scourge Beneficial, Synthesis, The Searing Exarch | H29: +N% increased Attack Speed | I29: attack_speed | J29: In game | K29: Weapon | L29: increased_attack_speed
A30: 29 | B30: Speed | C30: #% increased Action Speed | D30: (4-6)% increased Action Speed | E30: 75 | F30: Boots | G30: Corrupted, The Searing Exarch | H30: The fight clock runs N% slower | I30: fight clock | J30: Variant | K30: Boots, Amulet | L30: added_fight_clock adds seconds; this stretches every one. Glass World turned round
A31: 30 | B31: Speed | C31: #% increased Attack Speed while a Rare or Unique Enemy is Nearby | D31: (10-11)% increased Attack Speed while a Rare or Unique Enemy is Nearby | E31: 60 | F31: Bows, Claws, Daggers, One Hand Axes, One Hand Maces, One Hand Swords, Sceptres, Staves, Two Hand Maces, Two Hand Swords, Wands | G31: Crafting Bench | H31: +N% increased Attack Speed against elites and bosses | I31: elite flag | J31: New stat | K31: Boots, Ring
A32: 31 | B32: Map | C32: #% increased Movement Speed | D32: 35% increased Movement Speed | E32: 1 | F32: Amulets, Belts, Body Armours, Boots, Helmets, Rings | G32: Base, Corrupted, Crafting Bench, Essence, Scourge Beneficial, Synthesis, The Searing Exarch | H32: +N% increased Move Speed | I32: move_speed | J32: In game | K32: Boots | L32: increased_move_speed
A33: 32 | B33: On kill | C33: #% chance to gain Onslaught for # seconds on Kill | D33: (7-8)% chance to gain Onslaught for 4 seconds on Kill | E33: 1 | F33: Belts, Boots, Bows, Claws, Daggers, One Hand Axes, One Hand Maces, One Hand Swords, Quivers, Sceptres, Shields, Staves, Two Hand Maces, Two Hand Swords, Wands | G33: Corrupted, Delve, Scourge Beneficial, Synthesis | H33: N% chance a kill gives +20% Attack Speed for 4 seconds | I33: timed buffs | J33: New mechanic | K33: Boots, Weapon | L33: PoE's Onslaught; the timed-buff rows below share one system
A34: 33 | B34: On hit | C34: You gain Onslaught for # seconds when Hit | D34: You gain Onslaught for 3 seconds when Hit | E34: 45 | F34: Body Armours | G34: Essence, Scourge Beneficial | H34: A blow that lands on you gives +20% Attack Speed for N seconds | I34: timed buffs | J34: New mechanic | K34: Body | L34: Turns lost time into a comeback
A35: 34 | B35: On kill | C35: #% increased Effect of Onslaught on you | D35: (6-7)% increased Effect of Onslaught on you | E35: 68 | F35: Boots, Bows, Claws, Daggers, One Hand Axes, One Hand Maces, One Hand Swords, Sceptres, Staves, Two Hand Maces, Two Hand Swords, Wands | G35: Recombinator, The Searing Exarch | H35: Kill-speed bursts are N% stronger | I35: timed buffs | J35: New mechanic | K35: Ring
A36: 35 | B36: On kill | C36: #% chance to gain Unholy Might for # seconds on Kill | D36: 6% chance to gain Unholy Might for 3 seconds on Kill | E36: 1 | F36: Claws, Daggers, Staves, Wands | G36: Corrupted, Scourge Beneficial | H36: N% chance a kill gives +30% increased Damage for 4 seconds | I36: timed buffs | J36: New mechanic | K36: Weapon, Helmet
A37: 36 | B37: On kill | C37: #% chance to gain Phasing for # seconds on Kill | D37: (16-20)% chance to gain Phasing for 4 seconds on Kill | E37: 45 | F37: Quivers | G37: Scourge Beneficial | H37: N% chance a kill makes the next enemy blow miss | I37: timed buffs | J37: New mechanic | K37: Hood, Jerkin
A38: 37 | B38: On kill | C38: #% increased Skill Effect Duration | D38: (7-8)% increased Skill Effect Duration | E38: 1 | F38: Amulets, Belts | G38: Corrupted, The Eater of Worlds | H38: Buffs from kills last N% longer | I38: timed buffs | J38: New mechanic | K38: Amulet
A39: 38 | B39: Rage | C39: Gain # Rage on Attack Hit | D39: Gain 1 Rage on Attack Hit | E39: 75 | F39: Gloves | G39: The Searing Exarch | H39: Each blow builds N rage; a rage is +1% Damage, up to 30, draining away out of a fight | I39: new: rage | J39: New mechanic | K39: Weapon, Helmet | L39: Fast clicking builds it; a clicker's natural fit
A40: 39 | B40: Rage | C40: Inherent loss of Rage is #% slower | D40: Inherent loss of Rage is 20% slower | E40: 68 | F40: Helmets | G40: Infamous | H40: Rage drains N% slower | I40: rage | J40: New mechanic | K40: Ring
...

Sheet Tile & curse ideas
A1: # | B1: PoE map modifier | C1: Tile modifier for Kobold Clicker | D1: Fit | E1: Notes
A2: 1 | B2: Monsters have #% more Life | C2: Enemies have N% more health | D2: In game | E2: Thick-skinned; Iron Foes curse
A3: 2 | B3: #% increased Monster Damage | C3: Enemies hit N% harder | D3: In game | E3: Brutal; Bloodthirst curse
A4: 3 | B4: #% increased Monster Attack Speed | C4: Enemies attack N% faster | D4: In game | E4: Frenzied
A5: 4 | B5: Players have #% less Armour | C5: Only N% of your armour counts | D5: In game | E5: Piercing
A6: 5 | B6: Players have #% reduced Chance to Block | C6: Only N% of your block counts | D6: In game | E6: Sundering
A7: 6 | B7: Monsters have #% increased Accuracy Rating | C7: Only N% of your dodge counts | D7: In game | E7: Keen-eyed
A8: 7 | B8: #% increased Pack Size | C8: N more enemies on the same clock | D8: In game | E8: Horde
A9: 8 | B9: Area is inhabited by # additional Rare Monsters | C9: One enemy in N is an elite | D9: In game | E9: Elite Ground
A10: 9 | B10: Players have #% less Recovery Rate | C10: Only N% of your Time on Hit counts | D10: In game | E10: Miserly
A11: 10 | B11: Players are Cursed with Temporal Chains | C11: Your weapon swings N% slower on its own | D11: In game | E11: Stillness
A12: 11 | B12: Monsters Regenerate #% of Life per second | C12: Enemies heal N% of their health a second | D12: New | E12: Punishes slow kills; an idle build must out-damage it
A13: 12 | B13: Monsters gain #% of Maximum Life as Extra Maximum Energy Shield | C13: Enemies wear a shield of N% of their health that comes back after 3 seconds without a blow | D13: New | E13: Rewards steady swings over bursts
A14: 13 | B14: Monsters have #% increased Evasion Rating | C14: Enemies dodge N% of your blows | D14: New
A15: 14 | B15: Monsters take #% reduced Extra Damage from Critical Strikes | C15: Your crits deal N% less extra damage | D15: New | E15: Pushes off crit builds
A16: 15 | B16: Monsters have #% increased Critical Strike Chance | C16: One enemy blow in N lands twice as hard | D16: New
A17: 16 | B17: Monsters reflect #% of Physical Damage | C17: Each click costs N hundredths of a second | D17: New | E17: Turns clicking into a cost; idle builds shrug
A18: 17 | B18: Monsters gain an Endurance Charge on Hit | C18: Each blow an enemy lands makes it take 5% less damage | D18: New
A19: 18 | B19: Monsters have #% chance to Avoid Poison, Impale, and Bleeding | C19: Enemies cannot bleed or burn | D19: New | E19: Pushes off bleed and burn builds
A20: 19 | B20: Players are Cursed with Enfeeble | C20: You deal N% less damage | D20: New
A21: 20 | B21: Monsters Blind on Hit | C21: An enemy blow halves your Crit Chance for 4 seconds | D21: New
A22: 21 | B22: Monsters Poison on Hit | C22: Enemy blows go on costing time for 3 seconds | D22: New
A23: 22 | B23: Buffs on Players expire #% faster | C23: Your kill buffs end N% sooner | D23: Future | E23: Needs timed buffs
A24: 23 | B24: Monsters steal Power, Frenzy and Endurance charges on Hit | C24: Enemy blows take one of your stacks | D24: Future | E24: Needs fight stacks
A25: 24 | B25: Monsters cannot be Stunned | C25: Enemies cannot be stunned or knocked back | D25: Future | E25: Needs enemy control
A26: 25 | B26: Unique Boss deals #% increased Damage | C26: The lair's boss hits N% harder | D26: New | E26: For lairs
A27: 26 | B27: Unique Boss has #% increased Life | C27: The lair's boss has N% more health | D27: New | E27: For lairs
A28: 27 | B28: Rare Monsters each have # additional Modifiers | C28: Elites carry one more affix | D28: Future | E28: Needs elite affixes

Sheet All poedb candidates
A1: PoE modifier (poedb) | B1: PoE top tier | C1: PoE min item level | D1: PoE item classes | E1: PoE source | F1: Picked
A2: # Dexterity Requirement | B2: +(150-200) Dexterity Requirement | C2: 1 | D2: Body Armours, Boots, Bows, Claws, Daggers, Gloves, Helmets, One Hand Axes, One Hand Swords, Shields, Two Hand Swords | E2: Scourge Detrimental | F2: =IF(COUNTIF('Item modifiers'!$C:$C,A2)>0,"Yes","")
A3: # Intelligence Requirement | B3: +(150-200) Intelligence Requirement | C3: 1 | D3: Body Armours, Boots, Claws, Daggers, Gloves, Helmets, Sceptres, Shields, Staves, Wands | E3: Scourge Detrimental | F3: =IF(COUNTIF('Item modifiers'!$C:$C,A3)>0,"Yes","")
A4: # Strength Requirement | B4: +(150-200) Strength Requirement | C4: 1 | D4: Body Armours, Boots, Gloves, Helmets, One Hand Axes, One Hand Maces, One Hand Swords, Sceptres, Shields, Staves, Two Hand Maces, Two Hand Swords | E4: Scourge Detrimental | F4: =IF(COUNTIF('Item modifiers'!$C:$C,A4)>0,"Yes","")
A5: # metres to Melee Strike Range | B5: +0.1 metres to Melee Strike Range | C5: 56 | D5: Amulets | E5: Synthesis | F5: =IF(COUNTIF('Item modifiers'!$C:$C,A5)>0,"Yes","")
A6: # metres to Weapon Range | B6: +0.3 metres to Weapon Range | C6: 1 | D6: Claws, Daggers, One Hand Axes, One Hand Maces, One Hand Swords, Sceptres, Staves, Two Hand Maces, Two Hand Swords | E6: Corrupted, Scourge Beneficial, Synthesis | F6: =IF(COUNTIF('Item modifiers'!$C:$C,A6)>0,"Yes","")
A7: # to Accuracy Rating | B7: +(625-780) to Accuracy Rating | C7: 1 | D7: Amulets, Bows, Claws, Cobalt Jewel, Crimson Jewel, Daggers, Gloves, Helmets, One Hand Axes, One Hand Maces, One Hand Swords, Quivers, Rings, Sceptres, Shields, Staves, Two Hand Maces, Two Hand Swords, Viridian Jewel, Wands | E7: Base, Crafting Bench, Essence, Synthesis | F7: =IF(COUNTIF('Item modifiers'!$C:$C,A7)>0,"Yes","")
A8: # to Accuracy Rating per # Dexterity | B8: +2 to Accuracy Rating per 2 Dexterity | C8: 68 | D8: Helmets | E8: Haunted Modifiers | F8: =IF(COUNTIF('Item modifiers'!$C:$C,A8)>0,"Yes","")
A9: # to Accuracy Rating per Frenzy Charge | B9: +(43-45) to Accuracy Rating per Frenzy Charge | C9: 75 | D9: Gloves | E9: The Eater of Worlds | F9: =IF(COUNTIF('Item modifiers'!$C:$C,A9)>0,"Yes","")
A10: # to Armour | B10: +(461-540) to Armour | C10: 1 | D10: Belts, Body Armours, Boots, Gloves, Helmets, Rings, Shields | E10: Base, Crafting Bench, Essence, Scourge Beneficial, Synthesis | F10: =IF(COUNTIF('Item modifiers'!$C:$C,A10)>0,"Yes","") -> Yes
A11: # to Armour and Evasion Rating | B11: +(214-285) to Armour and Evasion Rating | C11: 60 | D11: Belts, Quivers | E11: Crafting Bench | F11: =IF(COUNTIF('Item modifiers'!$C:$C,A11)>0,"Yes","")
A12: # to Armour and Evasion Rating while Fortified | B12: +800 to Armour and Evasion Rating while Fortified | C12: 36 | D12: Amulets | E12: Synthesis | F12: =IF(COUNTIF('Item modifiers'!$C:$C,A12)>0,"Yes","")
A13: # to Armour if you've Hit an Enemy Recently | B13: +500 to Armour if you've Hit an Enemy Recently | C13: 1 | D13: Cobalt Jewel, Crimson Jewel, One Hand Axes, One Hand Maces, One Hand Swords, Sceptres, Staves, Two Hand Maces, Two Hand Swords, Viridian Jewel | E13: Delve | F13: =IF(COUNTIF('Item modifiers'!$C:$C,A13)>0,"Yes","")
... A379: Zealot's Oath | B379: Zealot's Oath | C379: 68 | D379: Body Armours | E379: Scourge Beneficial | F379: =IF(COUNTIF('Item modifiers'!$C:$C,A379)>0,"Yes","")
